#!/usr/bin/env python
#
# Copyright (c) 2012-2023 Snowflake Computing Inc. All rights reserved.
#

from __future__ import annotations

import asyncio
import errno
import json
import logging
import os
from test.unit.aio.mock_utils import mock_async_request_with_action, mock_connection
from test.unit.mock_utils import zero_backoff
from unittest.mock import AsyncMock, MagicMock, Mock, PropertyMock, patch
from uuid import uuid4

import aiohttp
import OpenSSL.SSL
import pytest

import snowflake.connector.aio
from snowflake.connector.aio._network import SnowflakeRestful
from snowflake.connector.compat import (
    BAD_GATEWAY,
    BAD_REQUEST,
    FORBIDDEN,
    GATEWAY_TIMEOUT,
    INTERNAL_SERVER_ERROR,
    OK,
    SERVICE_UNAVAILABLE,
    UNAUTHORIZED,
    BadStatusLine,
    IncompleteRead,
)
from snowflake.connector.errors import (
    DatabaseError,
    Error,
    ForbiddenError,
    InterfaceError,
    OperationalError,
    OtherHTTPRetryableError,
    ServiceUnavailableError,
)
from snowflake.connector.network import STATUS_TO_EXCEPTION, RetryRequest

pytestmark = pytest.mark.skipolddriver


THIS_DIR = os.path.dirname(os.path.realpath(__file__))


class Cnt:
    def __init__(self):
        self.c = 0

    def set(self, cnt):
        self.c = cnt

    def reset(self):
        self.set(0)


async def fake_connector() -> snowflake.connector.aio.SnowflakeConnection:
    conn = snowflake.connector.aio.SnowflakeConnection(
        user="user",
        account="account",
        password="testpassword",
        database="TESTDB",
        warehouse="TESTWH",
    )
    await conn.connect()
    return conn


@patch("snowflake.connector.aio._network.SnowflakeRestful._request_exec")
async def test_retry_reason(mockRequestExec):
    url = ""
    cnt = Cnt()

    async def mock_exec(session, method, full_url, headers, data, token, **kwargs):
        # take actions based on data["sqlText"]
        nonlocal url
        url = full_url
        data = json.loads(data)
        sql = data.get("sqlText", "default")
        success_result = {
            "success": True,
            "message": None,
            "data": {
                "token": "TOKEN",
                "masterToken": "MASTER_TOKEN",
                "idToken": None,
                "parameters": [{"name": "SERVICE_NAME", "value": "FAKE_SERVICE_NAME"}],
            },
        }
        cnt.c += 1
        if "retry" in sql:
            # error = HTTP Error 429
            if cnt.c < 3:  # retry twice for 429 error
                raise RetryRequest(OtherHTTPRetryableError(errno=429))
            return success_result
        elif "unknown error" in sql:
            # Raise unknown http error
            if cnt.c == 1:  # retry once for 100 error
                raise RetryRequest(OtherHTTPRetryableError(errno=100))
            return success_result
        elif "flip" in sql:
            if cnt.c == 1:  # retry first with 100
                raise RetryRequest(OtherHTTPRetryableError(errno=100))
            elif cnt.c == 2:  # then with 429
                raise RetryRequest(OtherHTTPRetryableError(errno=429))
            return success_result

        return success_result

    conn = await fake_connector()
    mockRequestExec.side_effect = mock_exec

    # ensure query requests don't have the retryReason if retryCount == 0
    cnt.reset()
    await conn.cmd_query("success", 0, uuid4())
    assert "retryReason" not in url
    assert "retryCount" not in url

    # ensure query requests have correct retryReason when retry reason is sent by server
    cnt.reset()
    await conn.cmd_query("retry", 0, uuid4())
    assert "retryReason=429" in url
    assert "retryCount=2" in url

    cnt.reset()
    await conn.cmd_query("unknown error", 0, uuid4())
    assert "retryReason=100" in url
    assert "retryCount=1" in url

    # ensure query requests have retryReason reset to 0 when no reason is given
    cnt.reset()
    await conn.cmd_query("success", 0, uuid4())
    assert "retryReason" not in url
    assert "retryCount" not in url

    # ensure query requests have retryReason gets updated with updated error code
    cnt.reset()
    await conn.cmd_query("flip", 0, uuid4())
    assert "retryReason=429" in url
    assert "retryCount=2" in url

    # ensure that disabling works and only suppresses retryReason
    conn._enable_retry_reason_in_query_response = False

    cnt.reset()
    await conn.cmd_query("retry", 0, uuid4())
    assert "retryReason" not in url
    assert "retryCount=2" in url

    cnt.reset()
    await conn.cmd_query("unknown error", 0, uuid4())
    assert "retryReason" not in url
    assert "retryCount=1" in url


async def test_request_exec():
    connection = mock_connection()
    connection.errorhandler = Error.default_errorhandler
    rest = SnowflakeRestful(
        host="testaccount.snowflakecomputing.com",
        port=443,
        connection=connection,
    )

    default_parameters = {
        "method": "POST",
        "full_url": "https://testaccount.snowflakecomputing.com/",
        "headers": {},
        "data": '{"code": 12345}',
        "token": None,
    }

    login_parameters = {
        **default_parameters,
        "full_url": "https://bad_id.snowflakecomputing.com:443/session/v1/login-request?request_id=s0m3-r3a11Y-rAnD0m-reqID&request_guid=s0m3-r3a11Y-rAnD0m-reqGUID",
    }

    # request mock
    output_data = {"success": True, "code": 12345}
    request_mock = AsyncMock()
    type(request_mock).status = PropertyMock(return_value=OK)
    request_mock.json.return_value = output_data

    # session mock
    session = AsyncMock()
    session.request.return_value = request_mock

    # success
    ret = await rest._request_exec(session=session, **default_parameters)
    assert ret == output_data, "output data"

    # retryable exceptions
    for errcode in [
        BAD_REQUEST,  # 400
        FORBIDDEN,  # 403
        INTERNAL_SERVER_ERROR,  # 500
        BAD_GATEWAY,  # 502
        SERVICE_UNAVAILABLE,  # 503
        GATEWAY_TIMEOUT,  # 504
        555,  # random 5xx error
    ]:
        type(request_mock).status = PropertyMock(return_value=errcode)
        try:
            await rest._request_exec(session=session, **default_parameters)
            pytest.fail("should fail")
        except RetryRequest as e:
            cls = STATUS_TO_EXCEPTION.get(errcode, OtherHTTPRetryableError)
            assert isinstance(e.args[0], cls), "must be internal error exception"

    # unauthorized
    type(request_mock).status = PropertyMock(return_value=UNAUTHORIZED)
    with pytest.raises(InterfaceError):
        await rest._request_exec(session=session, **default_parameters)

    # unauthorized with catch okta unauthorized error
    # TODO: what is the difference to InterfaceError?
    type(request_mock).status = PropertyMock(return_value=UNAUTHORIZED)
    with pytest.raises(DatabaseError):
        await rest._request_exec(
            session=session, catch_okta_unauthorized_error=True, **default_parameters
        )

    # forbidden on login-request raises ForbiddenError
    type(request_mock).status = PropertyMock(return_value=FORBIDDEN)
    with pytest.raises(ForbiddenError):
        await rest._request_exec(session=session, **login_parameters)

    class IncompleteReadMock(IncompleteRead):
        def __init__(self):
            IncompleteRead.__init__(self, "")

    # handle retryable exception
    for exc in [
        aiohttp.ConnectionTimeoutError,
        aiohttp.ClientConnectorError(MagicMock(), OSError(1)),
        asyncio.TimeoutError,
        IncompleteReadMock,
        AttributeError,
    ]:
        session = AsyncMock()
        session.request = Mock(side_effect=exc)

        try:
            await rest._request_exec(session=session, **default_parameters)
            pytest.fail("should fail")
        except RetryRequest as e:
            cause = e.args[0]
            assert (
                isinstance(cause, exc)
                if not isinstance(cause, aiohttp.ClientConnectorError)
                else cause == exc
            )

    # handle OpenSSL errors and BadStateLine
    for exc in [
        OpenSSL.SSL.SysCallError(errno.ECONNRESET),
        OpenSSL.SSL.SysCallError(errno.ETIMEDOUT),
        OpenSSL.SSL.SysCallError(errno.EPIPE),
        OpenSSL.SSL.SysCallError(-1),  # unknown
        BadStatusLine("fake"),
    ]:
        session = AsyncMock()
        session.request = Mock(side_effect=exc)
        try:
            await rest._request_exec(session=session, **default_parameters)
            pytest.fail("should fail")
        except RetryRequest as e:
            assert e.args[0] == exc, "same error instance"


async def test_fetch():
    connection = mock_connection()
    connection.errorhandler = Mock(return_value=None)

    rest = SnowflakeRestful(
        host="testaccount.snowflakecomputing.com", port=443, connection=connection
    )

    cnt = Cnt()
    default_parameters = {
        "method": "POST",
        "full_url": "https://testaccount.snowflakecomputing.com/",
        "headers": {"cnt": cnt},
        "data": '{"code": 12345}',
    }

    NOT_RETRYABLE = 1000

    class NotRetryableException(Exception):
        pass

    async def fake_request_exec(**kwargs):
        headers = kwargs.get("headers")
        cnt = headers["cnt"]
        await asyncio.sleep(3)
        if cnt.c <= 1:
            # the first two raises failure
            cnt.c += 1
            raise RetryRequest(Exception("can retry"))
        elif cnt.c == NOT_RETRYABLE:
            # not retryable exception
            raise NotRetryableException("cannot retry")
        else:
            # return success in the third attempt
            return {"success": True, "data": "valid data"}

    # inject a fake method
    rest._request_exec = fake_request_exec

    # first two attempts will fail but third will success
    cnt.reset()
    ret = await rest.fetch(timeout=10, **default_parameters)
    assert ret == {"success": True, "data": "valid data"}
    assert not rest._connection.errorhandler.called  # no error

    # first attempt to reach timeout even if the exception is retryable
    cnt.reset()
    ret = await rest.fetch(timeout=1, **default_parameters)
    assert ret == {}
    assert rest._connection.errorhandler.called  # error

    # not retryable excpetion
    cnt.set(NOT_RETRYABLE)
    with pytest.raises(NotRetryableException):
        await rest.fetch(timeout=7, **default_parameters)

    # first attempt fails and will not retry
    cnt.reset()
    default_parameters["no_retry"] = True
    ret = await rest.fetch(timeout=10, **default_parameters)
    assert ret == {}
    assert cnt.c == 1  # failed on first call - did not retry
    assert rest._connection.errorhandler.called  # error


async def test_secret_masking(caplog):
    connection = mock_connection()
    connection.errorhandler = Mock(return_value=None)

    rest = SnowflakeRestful(
        host="testaccount.snowflakecomputing.com", port=443, connection=connection
    )

    data = (
        '{"code": 12345,'
        ' "data": {"TOKEN": "_Y1ZNETTn5/qfUWj3Jedb", "PASSWORD": "dummy_pass"}'
        "}"
    )
    default_parameters = {
        "method": "POST",
        "full_url": "https://testaccount.snowflakecomputing.com/",
        "headers": {},
        "data": data,
    }

    class NotRetryableException(Exception):
        pass

    async def fake_request_exec(**kwargs):
        return None

    # inject a fake method
    rest._request_exec = fake_request_exec

    # first two attempts will fail but third will success
    with caplog.at_level(logging.ERROR):
        ret = await rest.fetch(timeout=10, **default_parameters)
    assert '"TOKEN": "****' in caplog.text
    assert '"PASSWORD": "****' in caplog.text
    assert ret == {}


async def test_retry_connection_reset_error(caplog):
    connection = mock_connection()
    connection.errorhandler = Mock(return_value=None)

    rest = SnowflakeRestful(
        host="testaccount.snowflakecomputing.com", port=443, connection=connection
    )

    data = (
        '{"code": 12345,'
        ' "data": {"TOKEN": "_Y1ZNETTn5/qfUWj3Jedb", "PASSWORD": "dummy_pass"}'
        "}"
    )
    default_parameters = {
        "method": "POST",
        "full_url": "https://testaccount.snowflakecomputing.com/",
        "headers": {},
        "data": data,
    }

    async def error_send(*args, **kwargs):
        raise OSError(104, "ECONNRESET")

    with patch(
        "snowflake.connector.aio._ssl_connector.SnowflakeSSLConnector.connect"
    ) as mock_conn, patch("aiohttp.client_reqrep.ClientRequest.send", error_send):
        with caplog.at_level(logging.DEBUG):
            await rest.fetch(timeout=10, **default_parameters)

        # this test is different from sync test because aiohttp automatically
        # closes the underlying broken socket if it encounters a connection reset error
        assert mock_conn.call_count > 1


@pytest.mark.parametrize("next_action", ("RETRY", "ERROR"))
@patch("aiohttp.ClientSession.request")
async def test_login_request_timeout(mockSessionRequest, next_action):
    """For login requests, all errors should be bubbled up as OperationalError for authenticator to handle"""
    mockSessionRequest.side_effect = mock_async_request_with_action(next_action)

    connection = mock_connection()
    rest = SnowflakeRestful(
        host="testaccount.snowflakecomputing.com", port=443, connection=connection
    )

    with pytest.raises(OperationalError):
        await rest.fetch(
            method="post",
            full_url="https://testaccount.snowflakecomputing.com/session/v1/login-request",
            headers=dict(),
        )


@pytest.mark.parametrize(
    "next_action_result",
    (("RETRY", ServiceUnavailableError), ("ERROR", OperationalError)),
)
@patch("aiohttp.ClientSession.request")
async def test_retry_request_timeout(mockSessionRequest, next_action_result):
    next_action, next_result = next_action_result
    mockSessionRequest.side_effect = mock_async_request_with_action(next_action, 5)
    # no backoff for testing
    connection = mock_connection(
        network_timeout=13,
        backoff_policy=zero_backoff,
    )
    connection.errorhandler = Error.default_errorhandler
    rest = SnowflakeRestful(
        host="testaccount.snowflakecomputing.com", port=443, connection=connection
    )

    with pytest.raises(next_result):
        await rest.fetch(
            method="post",
            full_url="https://testaccount.snowflakecomputing.com/queries/v1/query-request",
            headers=dict(),
        )

    # 13 seconds should be enough for authenticator to attempt thrice
    # however, loosen restrictions to avoid thread scheduling causing failure
    assert 1 < mockSessionRequest.call_count < 5
